Workbook
Name Slicer_CategoryName: #N/A
Name Slicer_CategoryName1: #N/A
Name Slicer_Country: #N/A
Name Slicer_Country1: #N/A
Name Slicer_Month_Name: #N/A
Name Slicer_Month_Name1: #N/A
Name Slicer_SubcategoryName: #N/A
Name Slicer_SubcategoryName1: #N/A
Name Slicer_Year: #N/A
Name Slicer_Year1: #N/A

Sheet Sheet1
G9: Country | H9: revenue | N9: Country | O9: revenue
C10: Category | D10: revenue | G10: =pivot!A16 -> Australia | H10: =pivot!B16 -> 7416456.2 | N10: =pivot!A16 -> Australia | O10: =pivot!B16 -> 7416456.2
C11: =pivot!D34 -> Bike Racks | D11: =pivot!E34 -> 36240 | G11: =pivot!A17 -> Canada | H11: =pivot!B17 -> 1769245.8 | N11: =pivot!A17 -> Canada | O11: =pivot!B17 -> 1769245.8
C12: =pivot!D35 -> Bike Stands | D12: =pivot!E35 -> 37206 | G12: =pivot!A18 -> France | H12: =pivot!B18 -> 2362643.3 | N12: =pivot!A18 -> France | O12: =pivot!B18 -> 2362643.3
C13: =pivot!D36 -> Bottles and Cages | D13: =pivot!E36 -> 107744.94 | G13: =pivot!A19 -> Germany | H13: =pivot!B19 -> 2524680 | N13: =pivot!A19 -> Germany | O13: =pivot!B19 -> 2524680
C14: =pivot!D37 -> Caps | D14: =pivot!E37 -> 35882.074 | G14: =pivot!A20 -> United Kingdom | H14: =pivot!B20 -> 2902562.1 | N14: =pivot!A20 -> United Kingdom | O14: =pivot!B20 -> 2902562.1
C15: =pivot!D38 -> Cleaners | D15: =pivot!E38 -> 13562.7 | G15: =pivot!A21 -> United States | H15: =pivot!B21 -> 7938999.4 | N15: =pivot!A21 -> United States | O15: =pivot!B21 -> 7938999.4
C16: =pivot!D39 -> Fenders | D16: =pivot!E39 -> 87040.8
C17: =pivot!D40 -> Gloves | D17: =pivot!E40 -> 62261.176
C18: =pivot!D41 -> Helmets | D18: =pivot!E41 -> 205833.94
C19: =pivot!D42 -> Hydration Packs | D19: =pivot!E42 -> 38218.05
C20: =pivot!D43 -> Jerseys | D20: =pivot!E43 -> 158564.94
C21: =pivot!D44 -> Mountain Bikes | D21: =pivot!E44 -> 8583747.7
C22: =pivot!D45 -> Road Bikes | D22: =pivot!E45 -> 11287183 | J22: Country | K22: Return quantiy
C23: =pivot!D46 -> Shorts | D23: =pivot!E46 -> 66070.56 | J23: =pivot!E65 -> Australia | K23: =pivot!F65 -> 404
C24: =pivot!D47 -> Socks | D24: =pivot!E47 -> 9556.37 | J24: =pivot!E66 -> Canada | K24: =pivot!F66 -> 238
C25: =pivot!D48 -> Tires and Tubes | D25: =pivot!E48 -> 380826.68 | J25: =pivot!E67 -> France | K25: =pivot!F67 -> 186
C26: =pivot!D49 -> Touring Bikes | D26: =pivot!E49 -> 3771564.7 | J26: =pivot!E68 -> Germany | K26: =pivot!F68 -> 163
C27: =pivot!D50 -> Vests | D27: =pivot!E50 -> 33083.5 | J27: =pivot!E69 -> United Kingdom | K27: =pivot!F69 -> 204
J28: =pivot!E70 -> United States | K28: =pivot!F70 -> 633

Sheet pivot
H1: sales
A5: Quantity Sold | B5: revenue | C5: Total orders | D5: profit | E5: profit margin | F5: AOV | G5: Active customer | H5: Total coast | M5: Month | N5: revenue
A6: 84174 | B6: 24914587 | C6: 25164 | D6: 10457715 | E6: 0.41974268 | F6: 990.08849 | G6: 17416 | H6: 14456871 | M6: 2020
M7: April | N7: 653364.04
A8: Category | B8: Total orders | D8: Category | E8: revenue | M8: August | N8: 536452.82
A9: Clothing | B9: 6976 | D9: Clothing | E9: 0.014666854 | M9: December | N9: 563761.53
A10: Bikes | B10: 13929 | D10: Bikes | E10: 0.94894189 | H10: Top 10 Product | I10: revenue | M10: February | N10: 532226.25
A11: Accessories | B11: 16983 | D11: Accessories | E11: 0.036391256 | H11: Mountain-200 Black, 46 | I11: 1241753.5 | M11: January | N11: 585312.65
D12: Grand Total | E12: 1 | H12: Mountain-200 Black, 42 | I12: 1233557.1 | M12: July | N12: 486115.01
H13: Mountain-200 Silver, 38 | I13: 1213851.9 | M13: June | N13: 669988.67
H14: Mountain-200 Silver, 46 | I14: 1182780.6 | M14: March | N14: 643436.1
A15: Country | B15: revenue | H15: Mountain-200 Black, 38 | I15: 1165936.9 | M15: May | N15: 659325.9
A16: Australia | B16: 7416456.2 | D16: Category | E16: profit | H16: Mountain-200 Silver, 42 | I16: 1133066.5 | M16: November | N16: 326611.15
A17: Canada | B17: 1769245.8 | D17: Clothing | E17: 0.015470597 | H17: Road-250 Black, 52 | I17: 689373.75 | M17: October | N17: 404276.6
A18: France | B18: 2362643.3 | D18: Bikes | E18: 0.93004713 | H18: Road-250 Red, 58 | I18: 661013.44 | M18: September | N18: 344062.87
A19: Germany | B19: 2524680 | D19: Accessories | E19: 0.054482269 | H19: Road-250 Black, 48 | I19: 641379.38 | M19: 2021
A20: United Kingdom | B20: 2902562.1 | H20: Road-150 Red, 48 | I20: 640510.33 | M20: April | N20: 494957.42
A21: United States | B21: 7938999.4 | M21: August | N21: 804193.39
M22: December | N22: 1635308.8
M23: February | N23: 474162.79
D24: Category | E24: Quantity Sold | F24: Return quantiy | G24: return rate | M24: January | N24: 432425.74
D25: Accessories | E25: 57809 | F25: 1130 | G25: 0.019547129 | M25: July | N25: 815356.47
D26: Bikes | E26: 13929 | F26: 429 | G26: 0.030799052 | M26: June | N26: 533824.98
D27: Clothing | E27: 12436 | F27: 269 | G27: 0.021630749 | M27: March | N27: 471961.88
M28: May | N28: 545534.74
A29: Customer | B29: sales | M29: November | N29: 1133913
A30: MR. MAURICE SHAN | B30: 12407.955 | M30: October | N30: 1029821.1
A31: MRS. JANET MUNOZ | B31: 12015.403 | M31: September | N31: 952743.49
A32: MRS. LISA CAI | B32: 11330.449 | M32: 2022
A33: MRS. LACEY ZHENG | B33: 11085.75 | D33: Subcategory | E33: revenue | M33: April | N33: 1527813.7
A34: MR. JORDAN TURNER | B34: 11022.4 | D34: Bike Racks | E34: 36240 | M34: February | N34: 1339241.3
A35: MR. FRANKLIN XU | B35: 10863.44 | D35: Bike Stands | E35: 37206 | M35: January | N35: 1274378.7
A36: MR. LARRY MUNOZ | B36: 10852.034 | D36: Bottles and Cages | E36: 107744.94 | M36: June | N36: 1826987.1
A37: MRS. KATE ANAND | B37: 10436.508 | D37: Caps | E37: 35882.074 | M37: March | N37: 1448596.1
A38: MR. LARRY VAZQUEZ | B38: 10394.984 | D38: Cleaners | E38: 13562.7 | M38: May | N38: 1768432.5
A39: MRS. ARIANA GRAY | B39: 10391.43 | D39: Fenders | E39: 87040.8
D40: Gloves | E40: 62261.176
D41: Helmets | E41: 205833.94
D42: Hydration Packs | E42: 38218.05
D43: Jerseys | E43: 158564.94
...

Sheet  sales Dashboard

Sheet Return Dashboard
